Workbook

Sheet LEEME_CIERRE
A1: IA + TEA | Cierre analitico
A2: Version congelada: 8 septiembre 2026 | Una referencia = un informe; no una cohorte independiente.
A4: Control | B4: Valor | C4: Interpretacion
A5: Registros conservados | B5: =COUNTA('BASE_CIERRE'!$A$5:$A$458) -> 454 | C5: Todos los registros originales permanecen auditables; no se borraron filas.
A6: Incluidos en sintesis principal | B6: =COUNTIFS('BASE_CIERRE'!$G$5:$G$458,1) -> 428 | C6: Corpus ampliado tras 26 exclusiones documentadas. No equivale a 428 estudios verificados en texto completo en esta pasada.
A7: Exclusiones de esta auditoria | B7: =COUNTIFS('BASE_CIERRE'!$F$5:$F$458,"Exclude") -> 26 | C7: Tipos no elegibles, ausencia de IA pertinente, tema/poblacion fuera de alcance y dos retractados.
A8: Etapa clinica resuelta | B8: =COUNTIFS('BASE_CIERRE'!$AF$5:$AF$458,1) -> 397 | C8: Base de los porcentajes por las cinco etapas; 31 informes sin etapa unica permanecen en el corpus.
A9: Uso de IA evaluado | B9: =COUNTIFS('BASE_CIERRE'!$G$5:$G$458,1,'BASE_CIERRE'!$M$5:$M$458,"Evaluated at point of use")+COUNTIFS('BASE_CIERRE'!$G$5:$G$458,1,'BASE_CIERRE'!$M$5:$M$458,"Evaluated AI-supported intervention")+COUNTIFS('BASE_CIERRE'!$G$5:$G$458,1,'BASE_CIERRE'!$M$5:$M$458,"Evaluated care-delivery platform") -> 19 | C9: 8 evaluaciones en punto de uso, 10 intervenciones y 1 plataforma de atencion; no implica eficacia clinica demostrada.
A10: Sin alertas editoriales | B10: =COUNTIFS('BASE_CIERRE'!$AD$5:$AD$458,1) -> 426 | C10: Excluye dos expresiones de preocupacion, ademas de los retractados ya excluidos.
A11: Sensibilidad conservadora | B11: =COUNTIFS('BASE_CIERRE'!$AE$5:$AE$458,1) -> 410 | C11: Excluye alertas editoriales y 16 cautelas adicionales de alcance/fuente.
A12: Sensibilidad de etapa directa | B12: =COUNTIFS('BASE_CIERRE'!$AG$5:$AG$458,1) -> 385 | C12: Subconjunto conservador con una de las cinco etapas clinicas resuelta.
A13: Verificacion humana de esta recodificacion | B13: No documentada | C13: No atribuir esta auditoria a los dos revisores ni afirmar concordancia independiente.
A14: PRISMA inicial | B14: No reconstruible | C14: El manuscrito informa 282; la base historica contiene 276. Falta trazabilidad de seis referencias y del flujo inicial.
A15: Entrada de los scripts | B15: BASE_CIERRE | C15: Las hojas originales estan ocultas como archivo. No mezclar con los antiguos XLSX ni con las cifras 282/273/260.
A16: Inicio para redactar | B16: RESULTADOS_EN | C16: Texto en ingles, tablas con denominadores, limitaciones y reemplazos numericos. No se reescribio el manuscrito original.
A18: RESUMEN_CIERRE | B18: Abrir | C18: Distribuciones y denominadores recalculables.
A19: RQ1_PERFILES | B19: Abrir | C19: Tecnica x fuente x etapa; incluye todos los perfiles.
A20: RQ2_INTEGRACION | B20: Abrir | C20: Etapa, madurez de uso, rol y momento de decision.
A21: RQ3_PRACTICAS | B21: Abrir | C21: Cuatro practicas principales y analisis estricto adicional.
A22: RQ3_PERFILES | B22: Abrir | C22: Numeradores, no reportados e indeterminados en cada perfil.
A23: SENSIBILIDAD | B23: Abrir | C23: Robustez de los conteos a alertas y criterios conservadores.
A24: EVIDENCIA_CIERRE | B24: Abrir | C24: Fuentes, texto original, notas y procedencia de las correcciones.
A25: CAMBIOS_CIERRE | B25: Abrir | C25: Antes/despues por campo; 2,449 cambios trazables.
... A27: VALIDACION | B27: Abrir | C27: Controles computacionales; no auditoria humana ficticia.

Sheet BASE_CIERRE
A1: Base unica de analisis
A2: Modificar solamente codigos basados en evidencia; todos los resumenes se derivan de esta hoja. Las columnas de inclusion son formulas.
A4: study_id | B4: cohort | C4: title | D4: doi | E4: year | F4: eligibility | G4: include_main | H4: stage_primary | I4: ai_type | J4: data_source_primary | K4: algorithm_main | L4: algorithm_family | M4: rq2_status | N4: rq2_role | O4: decision_timing_coded | P4: observed_decision_timing | Q4: external_validation | R4: multisource_integration | S4: xai_broad | T4: xai_strict | U4: cross_site_robustness | V4: multisite_dataset | W4: multisource_data | X4: prospective_evaluation | Y4: prospective_data_collection | Z4: xai_partial | AA4: integrity_status | AB4: integrity_caution | AC4: source_scope_caution | AD4: include_no_editorial_alert | AE4: include_conservative | AF4: stage_resolved | AG4: include_direct_stage_sensitivity | AH4: source_level | AI4: source_url | AJ4: source_locator | AK4: rationale | AL4: exclusion_reason | AM4: endpoint_level | AN4: source_scope_caution_detail | AO4: publication_status_update | AP4: independent_human_verification | AQ4: assessor | AR4: original_reviewer | AS4: original_access_status
A5: 1 | B5: Historical | C5: A Clinically Interpretable Approach for Early Detection of Autism Using Machine Learning With Explainable AI | D5: 10.1109/access.2025.3586314 | E5: 2025 | F5: Include | G5: =IF(F5="Include",1,0) -> 1 | H5: Screening | I5: Machine Learning | J5: Structured clinical/questionnaire data | K5: Random Forest | L5: Random forest | M5: Proposed only | N5: Triage/questionnaire assessment | O5: Pre-decision | P5: Not observed in assessed sources | Q5: Not reported in assessed sources | R5: Not reported in assessed sources | S5: Reported | T5: Reported | U5: Not reported in assessed sources | V5: Not reported in assessed sources | W5: Not reported in assessed sources | X5: Not reported in assessed sources | Y5: Not ascertainable | Z5: Not reported in assessed sources | AA5: Not recorded | AB5: 0 | AC5: 0 | AD5: =IF(AND(G5=1,AB5=0),1,0) -> 1 | AE5: =IF(AND(AD5=1,AC5=0),1,0) -> 1 | AF5: =IF(AND(G5=1,H5<>"Not specified"),1,0) -> 1 | AG5: =IF(AND(AE5=1,AF5=1),1,0) -> 1 | AH5: Supplied abstract/coding notes; no new full-text verification | AI5: https://doi.org/10.1109/access.2025.3586314 | AJ5: EVIDENCIA; original abstract/coding notes and lot source trace; Historical signals: title/abstract/notes; full-text completion not independently established | AK5: Public age-specific screening datasets; five-fold CV and SHAP. Physician interpretation is proposed, not evaluated in a clinical workflow. Background mentions do not establish five clinical stages. | AL5: Not applicable | AM5: Not separately specified | AO5: No additional status determination | AP5: Not documented for this recharting | AQ5: ChatGPT-assisted evidence recharting, 2026-09-08 | AS5: Not recorded; historical inclusion retained
A6: 2 | B6: Historical | C6: Searching for a minimal set of behaviors for autism detection through feature selection-based machine learning | D6: 10.1038/tp.2015.7 | E6: 2015 | F6: Include | G6: =IF(F6="Include",1,0) -> 1 | H6: Screening | I6: Machine Learning | J6: Structured clinical/questionnaire data | K6: Multiple algorithms compared (8; primary not specified) | L6: Multiple/not uniquely specified | M6: Proposed only | N6: Triage/questionnaire assessment | O6: Pre-decision | P6: Not observed in assessed sources | Q6: Not reported in assessed sources | R6: Not reported in assessed sources | S6: Reported | T6: Not reported in assessed sources | U6: Not reported in assessed sources | V6: Not reported in assessed sources | W6: Not reported in assessed sources | X6: Not reported in assessed sources | Y6: Not ascertainable | Z6: Reported | AA6: Not recorded | AB6: 0 | AC6: 0 | AD6: =IF(AND(G6=1,AB6=0),1,0) -> 1 | AE6: =IF(AND(AD6=1,AC6=0),1,0) -> 1 | AF6: =IF(AND(G6=1,H6<>"Not specified"),1,0) -> 1 | AG6: =IF(AND(AE6=1,AF6=1),1,0) -> 1 | AH6: Supplied abstract/coding notes; no new full-text verification | AI6: https://doi.org/10.1038/tp.2015.7 | AJ6: EVIDENCIA; original abstract/coding notes and lot source trace; Historical signals: title/abstract/notes; full-text completion not independently established | AK6: ADOS score sheets are structured behavioral records, not unspecified data. The reduced behavioral set is proposed for preliminary triage; no prospective use of the resulting model is described. | AL6: Not applicable | AM6: Not separately specified | AO6: No additional status determination | AP6: Not documented for this recharting | AQ6: ChatGPT-assisted evidence recharting, 2026-09-08 | AR6: RA | AS6: Not recorded; historical inclusion retained
A7: 3 | B7: Historical | C7: The use of data independent acquisition based proteomic analysis and machine learning to reveal potential biomarkers for autism spectrum disorder | D7: 10.1016/j.jprot.2023.104872 | E7: 2023 | F7: Include | G7: =IF(F7="Include",1,0) -> 1 | H7: Diagnosis | I7: Machine Learning | J7: Biological/omics | K7: Not specified | L7: Multiple/not uniquely specified | M7: Research only | N7: Automated measurement/classification | O7: Not observed in assessed sources | P7: Not observed in assessed sources | Q7: Reported | R7: Not reported in assessed sources | S7: Not reported in assessed sources | T7: Not reported in assessed sources | U7: Not reported in assessed sources | V7: Not reported in assessed sources | W7: Not reported in assessed sources | X7: Not reported in assessed sources | Y7: Not ascertainable | Z7: Not reported in assessed sources | AA7: Not recorded | AB7: 0 | AC7: 0 | AD7: =IF(AND(G7=1,AB7=0),1,0) -> 1 | AE7: =IF(AND(AD7=1,AC7=0),1,0) -> 1 | AF7: =IF(AND(G7=1,H7<>"Not specified"),1,0) -> 1 | AG7: =IF(AND(AE7=1,AF7=1),1,0) -> 1 | AH7: Supplied abstract/coding notes; no new full-text verification | AI7: https://doi.org/10.1016/j.jprot.2023.104872 | AJ7: EVIDENCIA; original abstract/coding notes and lot source trace; Historical signals: title/abstract/notes; full-text completion not independently established | AK7: Plasma proteomics with DIA/MRM and machine-learning biomarker selection. Molecular assay verification alone does not establish external validation of the predictive model. | AL7: Not applicable | AM7: Not separately specified | AO7: No additional status determination | AP7: Not documented for this recharting | AQ7: ChatGPT-assisted evidence recharting, 2026-09-08 | AR7: RA | AS7: Not recorded; historical inclusion retained
A8: 4 | B8: Historical | C8: Cognitive Disorder Detection Used for Early Autism Screening Using Deep Learning | D8: 10.1007/978-981-96-3942-7_18 | E8: 2025 | F8: Exclude | G8: =IF(F8="Include",1,0) -> 0 | H8: Excluded | I8: Excluded | J8: Excluded | K8: MLP | L8: MLP/ANN | M8: Excluded | N8: Excluded | O8: Not applicable - excluded | P8: Not applicable - excluded | Q8: Not reported in assessed sources | R8: Not reported in assessed sources | S8: Not reported in assessed sources | T8: Not reported in assessed sources | U8: Not reported in assessed sources | V8: Not reported in assessed sources | W8: Not reported in assessed sources | X8: Not reported in assessed sources | Y8: Not ascertainable | Z8: Not reported in assessed sources | AA8: Not recorded | AB8: 0 | AC8: 0 | AD8: =IF(AND(G8=1,AB8=0),1,0) -> 0 | AE8: =IF(AND(AD8=1,AC8=0),1,0) -> 0 | AF8: =IF(AND(G8=1,H8<>"Not specified"),1,0) -> 0 | AG8: =IF(AND(AE8=1,AF8=1),1,0) -> 0 | AH8: Publisher abstract and bibliographic metadata | AI8: https://link.springer.com/chapter/10.1007/978-981-96-3942-7_18 | AJ8: Publisher abstract and references | AK8: The abstract describes CATest validation for mild cognitive disorder, Alzheimer disease and other neurological conditions rather than empirical ASD-specific modeling. Title wording alone does not establish eligibility. | AL8: EC2 - Wrong condition / population | AM8: Not separately specified | AO8: No additional status determination | AP8: Not documented for this recharting | AQ8: ChatGPT-assisted evidence recharting, 2026-09-08 | AS8: Not recorded; historical inclusion retained
A9: 5 | B9: Historical | C9: Metabolomics as a tool for discovery of biomarkers of autism spectrum disorder in the blood plasma of children | D9: 10.1371/journal.pone.0112445 | E9: 2014 | F9: Include | G9: =IF(F9="Include",1,0) -> 1 | H9: Diagnosis | I9: Machine Learning | J9: Biological/omics | K9: SVM / PLS-DA | L9: SVM | M9: Research only | N9: Automated measurement/classification | O9: Not observed in assessed sources | P9: Not observed in assessed sources | Q9: Not reported in assessed sources | R9: Reported | S9: Reported | T9: Not reported in assessed sources | U9: Not reported in assessed sources | V9: Not reported in assessed sources | W9: Reported | X9: Not reported in assessed sources | Y9: Not ascertainable | Z9: Reported | AA9: Not recorded | AB9: 0 | AC9: 0 | AD9: =IF(AND(G9=1,AB9=0),1,0) -> 1 | AE9: =IF(AND(AD9=1,AC9=0),1,0) -> 1 | AF9: =IF(AND(G9=1,H9<>"Not specified"),1,0) -> 1 | AG9: =IF(AND(AE9=1,AF9=1),1,0) -> 1 | AH9: Primary-source full text (targeted sections) | AI9: https://journals.plos.org/plosone/article?id=10.1371/journal.pone.0112445 | AJ9: Methods: Training and Independent Validation Sets; Classification Modeling; Results: Validation Set Model Performance | AK9: Metabolomic classification and feature-ranking study. The held-out 21 participants were randomly partitioned from the same 82-participant cohort; this is internal holdout validation, despite the authors' external-sample terminology. | AL9: Not applicable | AM9: Not separately specified | AO9: No additional status determination | AP9: Not documented for this recharting | AQ9: ChatGPT-assisted evidence recharting, 2026-09-08 | AR9: RA | AS9: Not recorded; historical inclusion retained
A10: 6 | B10: Historical | C10: Sparsifying machine learning models identify stable subsets of predictive features for behavioral detection of autism | D10: 10.1186/s13229-017-0180-6 | E10: 2017 | F10: Include | G10: =IF(F10="Include",1,0) -> 1 | H10: Screening | I10: Machine Learning | J10: Structured clinical/questionnaire data | K10: Multiple sparse models (logistic regression / linear SVM) | L10: Composite/ensemble pipeline | M10: Proposed only | N10: Triage/questionnaire assessment | O10: Pre-decision | P10: Not observed in assessed sources | Q10: Not reported in assessed sources | R10: Not reported in assessed sources | S10: Reported | T10: Not reported in assessed sources | U10: Not reported in assessed sources | V10: Not reported in assessed sources | W10: Not reported in assessed sources | X10: Not reported in assessed sources | Y10: Not ascertainable | Z10: Reported | AA10: Not recorded | AB10: 0 | AC10: 0 | AD10: =IF(AND(G10=1,AB10=0),1,0) -> 1 | AE10: =IF(AND(AD10=1,AC10=0),1,0) -> 1 | AF10: =IF(AND(G10=1,H10<>"Not specified"),1,0) -> 1 | AG10: =IF(AND(AE10=1,AF10=1),1,0) -> 1 | AH10: Supplied abstract/coding notes; no new full-text verification | AI10: https://doi.org/10.1186/s13229-017-0180-6 | AJ10: EVIDENCIA; original abstract/coding notes and lot source trace; Historical signals: title/abstract/notes; full-text completion not independently established | AK10: ADOS score sheets and demographic covariates; sparse models intended to shorten assessment. No clinical use of predictions is evaluated. Comparing ML models is not hybrid ML/DL integration. | AL10: Not applicable | AM10: Not separately specified | AO10: No additional status determination | AP10: Not documented for this recharting | AQ10: ChatGPT-assisted evidence recharting, 2026-09-08 | AS10: Not recorded; historical inclusion retained
A11: 7 | B11: Historical | C11: Transformer-based deep learning ensemble framework predicts autism spectrum disorder using health administrative and birth registry data | D11: 10.1038/s41598-025-90216-8 | E11: 2025 | F11: Include | G11: =IF(F11="Include",1,0) -> 1 | H11: Prognosis | I11: Deep Learning | J11: Structured clinical/questionnaire data | K11: Transformer ensemble | L11: Transformer | M11: Proposed only | N11: Risk/trajectory estimation | O11: Pre-decision | P11: Not observed in assessed sources | Q11: Not reported in assessed sources | R11: Reported | S11: Reported | T11: Not ascertainable | U11: Not reported in assessed sources | V11: Not reported in assessed sources | W11: Reported | X11: Not reported in assessed sources | Y11: Not ascertainable | Z11: Reported | AA11: Not recorded | AB11: 0 | AC11: 0 | AD11: =IF(AND(G11=1,AB11=0),1,0) -> 1 | AE11: =IF(AND(AD11=1,AC11=0),1,0) -> 1 | AF11: =IF(AND(G11=1,H11<>"Not specified"),1,0) -> 1 | AG11: =IF(AND(AE11=1,AF11=1),1,0) -> 1 | AH11: Supplied abstract/coding notes; no new full-text verification | AI11: https://doi.org/10.1038/s41598-025-90216-8 | AJ11: EVIDENCIA; original abstract/coding notes and lot source trace; Historical signals: title/abstract/notes; full-text completion not independently established | AK11: Linked maternal-newborn administrative and registry records predict a future ASD diagnosis at 18-60 months. Population prescreening is a proposed use; the implemented endpoint is prognostic. | AL11: Not applicable | AM11: Not separately specified | AO11: No additional status determination | AP11: Not documented for this recharting | AQ11: ChatGPT-assisted evidence recharting, 2026-09-08 | AR11: RA | AS11: Not recorded; historical inclusion retained
A12: 8 | B12: Historical | C12: A Closed-Loop Ear-Worn Wearable EEG System with Real-Time Passive Electrode Skin Impedance Measurement for Early Autism Detection † | D12: 10.3390/s24237489 | E12: 2024 | F12: Include | G12: =IF(F12="Include",1,0) -> 1 | H12: Screening | I12: Machine Learning | J12: Physiological signals | K12: Not specified | L12: Multiple/not uniquely specified | M12: Proposed only | N12: Mobile assessment | O12: Pre-decision | P12: Not observed in assessed sources | Q12: Not reported in assessed sources | R12: Not reported in assessed sources | S12: Not reported in assessed sources | T12: Not reported in assessed sources | U12: Not reported in assessed sources | V12: Not reported in assessed sources | W12: Not reported in assessed sources | X12: Not reported in assessed sources | Y12: Not ascertainable | Z12: Not reported in assessed sources | AA12: Not recorded | AB12: 0 | AC12: 0 | AD12: =IF(AND(G12=1,AB12=0),1,0) -> 1 | AE12: =IF(AND(AD12=1,AC12=0),1,0) -> 1 | AF12: =IF(AND(G12=1,H12<>"Not specified"),1,0) -> 1 | AG12: =IF(AND(AE12=1,AF12=1),1,0) -> 1 | AH12: Supplied abstract/coding notes; no new full-text verification | AI12: https://doi.org/10.3390/s24237489 | AJ12: EVIDENCIA; original abstract/coding notes and lot source trace; Historical signals: title/abstract/notes; full-text completion not independently established | AK12: Ear-worn EEG hardware with on-chip classification is bench-tested using the Old Dominion University ASD dataset. A deployed wearable screening workflow is proposed, not demonstrated by a real-time hardware benchmark. | AL12: Not applicable | AM12: Not separately specified | AO12: No additional status determination | AP12: Not documented for this recharting | AQ12: ChatGPT-assisted evidence recharting, 2026-09-08 | AS12: Not recorded; historical inclusion retained
A13: 9 | B13: Historical | C13: An automated assessment framework for atypical prosody and stereotyped idiosyncratic phrases related to autism spectrum disorder | D13: 10.1016/j.csl.2018.11.002 | E13: 2019 | F13: Include | G13: =IF(F13="Include",1,0) -> 1 | H13: Diagnosis | I13: Hybrid | J13: Audio/voice | K13: CNN/RNN and SVM | L13: Composite/ensemble pipeline | M13: Research only | N13: Automated measurement/classification | O13: Not observed in assessed sources | P13: Not observed in assessed sources | Q13: Not reported in assessed sources | R13: Not ascertainable | S13: Not reported in assessed sources | T13: Not reported in assessed sources | U13: Not reported in assessed sources | V13: Not reported in assessed sources | W13: Reported | X13: Not reported in assessed sources | Y13: Not ascertainable | Z13: Not reported in assessed sources | AA13: Not recorded | AB13: 0 | AC13: 0 | AD13: =IF(AND(G13=1,AB13=0),1,0) -> 1 | AE13: =IF(AND(AD13=1,AC13=0),1,0) -> 1 | AF13: =IF(AND(G13=1,H13<>"Not specified"),1,0) -> 1 | AG13: =IF(AND(AE13=1,AF13=1),1,0) -> 1 | AH13: Supplied abstract/coding notes; no new full-text verification | AI13: https://doi.org/10.1016/j.csl.2018.11.002 | AJ13: EVIDENCIA; original abstract/coding notes and lot source trace; Historical signals: title/abstract/notes; full-text completion not independently established | AK13: Acoustic and transcript-based ADOS-code prediction is evaluated offline. Audio and transcript tasks are described separately; classifier score fusion is not itself evidence of independent-source fusion. | AL13: Not applicable | AM13: Not separately specified | AO13: No additional status determination | AP13: Not documented for this recharting | AQ13: ChatGPT-assisted evidence recharting, 2026-09-08 | AS13: Not recorded; historical inclusion retained
A14: 10 | B14: Historical | C14: Artificial Intelligence Driven Predictive Analysis of Acoustic and Linguistic Behaviors for ASD Identification | D14: 10.1109/tai.2024.3439288 | E14: 2024 | F14: Include | G14: =IF(F14="Include",1,0) -> 1 | H14: Diagnosis | I14: Not specified | J14: Audio/voice | K14: Not specified | L14: Multiple/not uniquely specified | M14: Research only | N14: Automated measurement/classification | O14: Not observed in assessed sources | P14: Not observed in assessed sources | Q14: Not reported in assessed sources | R14: Not reported in assessed sources | S14: Not reported in assessed sources | T14: Not reported in assessed sources | U14: Not reported in assessed sources | V14: Not reported in assessed sources | W14: Not reported in assessed sources | X14: Not reported in assessed sources | Y14: Not ascertainable | Z14: Not reported in assessed sources | AA14: Not recorded | AB14: 0 | AC14: 0 | AD14: =IF(AND(G14=1,AB14=0),1,0) -> 1 | AE14: =IF(AND(AD14=1,AC14=0),1,0) -> 1 | AF14: =IF(AND(G14=1,H14<>"Not specified"),1,0) -> 1 | AG14: =IF(AND(AE14=1,AF14=1),1,0) -> 1 | AH14: Supplied abstract/coding notes; no new full-text verification | AI14: https://doi.org/10.1109/tai.2024.3439288 | AJ14: EVIDENCIA; original abstract/coding notes and lot source trace; Historical signals: title/abstract/notes; full-text completion not independently established | AK14: Speech-derived acoustic and linguistic biomarkers are evaluated in Hindi and English; no active clinician-facing workflow is documented in the assessed abstract. Acoustic and linguistic representations from speech; language variation is not independent input modality. | AL14: Not applicable | AM14: Not separately specified | AO14: No additional status determination | AP14: Not documented for this recharting | AQ14: ChatGPT-assisted evidence recharting, 2026-09-08 | AS14: Not recorded; historical inclusion retained
A15: 11 | B15: Historical | C15: Data Mining-Based Model for Computer-Aided Diagnosis of Autism and Gelotophobia: Mixed Methods Deep Learning Approach. | D15: 10.2196/72115 | E15: 2025 | F15: Include | G15: =IF(F15="Include",1,0) -> 1 | H15: Diagnosis | I15: Deep Learning | J15: Multiple source categories | K15: DeepFace with MLP classifier | L15: MLP/ANN | M15: Proposed only | N15: Diagnostic decision support | O15: In-decision | P15: Not observed in assessed sources | Q15: Not reported in assessed sources | R15: Reported | S15: Not reported in assessed sources | T15: Not reported in assessed sources | U15: Not reported in assessed sources | V15: Not reported in assessed sources | W15: Reported | X15: Not reported in assessed sources | Y15: Not ascertainable | Z15: Not reported in assessed sources | AA15: Expression of Concern | AB15: 1 | AC15: 0 | AD15: =IF(AND(G15=1,AB15=0),1,0) -> 0 | AE15: =IF(AND(AD15=1,AC15=0),1,0) -> 0 | AF15: =IF(AND(G15=1,H15<>"Not specified"),1,0) -> 1 | AG15: =IF(AND(AE15=1,AF15=1),1,0) -> 0 | AH15: Primary-source full text (targeted sections) | AI15: https://formative.jmir.org/2026/1/e91833/ | AJ15: Editorial notice, 23 January 2026 | AK15: Facial-image classification and questionnaire-assisted gelotophobia assessment are proposed for clinical use. Retain the expression-of-concern flag; diagnostic performance is not evidence of deployment. | AL15: Not applicable | AM15: Not separately specified | AO15: No additional status determination | AP15: Not documented for this recharting | AQ15: ChatGPT-assisted evidence recharting, 2026-09-08 | AS15: Not recorded; historical inclusion retained
A16: 12 | B16: Historical | C16: Effect of Wearable Digital Intervention for Improving Socialization in Children with Autism Spectrum Disorder: A Randomized Clinical Trial | D16: 10.1001/jamapediatrics.2019.0285 | E16: 2019 | F16: Include | G16: =IF(F16="Include",1,0) -> 1 | H16: Monitoring/intervention | I16: Not specified | J16: Behavioral images/video/gaze/movement | K16: Computer vision classifier (family not specified) | L16: Multiple/not uniquely specified | M16: Evaluated AI-supported intervention | N16: Adaptive intervention | O16: Post-decision | P16: Post-decision | Q16: Not reported in assessed sources | R16: Not reported in assessed sources | S16: Not reported in assessed sources | T16: Not reported in assessed sources | U16: Not reported in assessed sources | V16: Not reported in assessed sources | W16: Not reported in assessed sources | X16: Reported | Y16: Not ascertainable | Z16: Not reported in assessed sources | AA16: Not recorded | AB16: 0 | AC16: 0 | AD16: =IF(AND(G16=1,AB16=0),1,0) -> 1 | AE16: =IF(AND(AD16=1,AC16=0),1,0) -> 1 | AF16: =IF(AND(G16=1,H16<>"Not specified"),1,0) -> 1 | AG16: =IF(AND(AE16=1,AF16=1),1,0) -> 1 | AH16: Supplied abstract/coding notes; no new full-text verification | AI16: https://doi.org/10.1001/jamapediatrics.2019.0285 | AJ16: EVIDENCIA; original abstract/coding notes and lot source trace; Historical signals: title/abstract/notes; full-text completion not independently established | AK16: Superpower Glass provides AI-generated facial-expression feedback in a randomized home intervention. Standard ABA therapy and outcome scales are not additional AI input modalities. | AL16: Not applicable | AM16: Not separately specified | AO16: No additional status determination | AP16: Not documented for this recharting | AQ16: ChatGPT-assisted evidence recharting, 2026-09-08 | AS16: Not recorded; historical inclusion retained
A17: 13 | B17: Historical | C17: Feature Signature Discovery for Autism Detection: An Automated Machine Learning Based Feature Ranking Framework | D17: 10.1155/2023/6330002 | E17: 2023 | F17: Include | G17: =IF(F17="Include",1,0) -> 1 | H17: Screening | I17: Machine Learning | J17: Structured clinical/questionnaire data | K17: AutoML / feature-ranking framework | L17: Other specified method | M17: Research only | N17: Automated measurement/classification | O17: Not observed in assessed sources | P17: Not observed in assessed sources | Q17: Not reported in assessed sources | R17: Not reported in assessed sources | S17: Reported | T17: Not reported in assessed sources | U17: Not reported in assessed sources | V17: Not reported in assessed sources | W17: Not reported in assessed sources | X17: Not reported in assessed sources | Y17: Not ascertainable | Z17: Reported | AA17: Not recorded | AB17: 0 | AC17: 0 | AD17: =IF(AND(G17=1,AB17=0),1,0) -> 1 | AE17: =IF(AND(AD17=1,AC17=0),1,0) -> 1 | AF17: =IF(AND(G17=1,H17<>"Not specified"),1,0) -> 1 | AG17: =IF(AND(AE17=1,AF17=1),1,0) -> 1 | AH17: Supplied abstract/coding notes; no new full-text verification | AI17: https://doi.org/10.1155/2023/6330002 | AJ17: EVIDENCIA; original abstract/coding notes and lot source trace; Historical signals: title/abstract/notes; full-text completion not independently established | AK17: Q-CHAT-based tabular screening datasets and automated ML model ranking. Discussion of deep-learning comparators does not make the proposed AutoML framework deep learning. | AL17: Not applicable | AM17: Not separately specified | AO17: No additional status determination | AP17: Not documented for this recharting | AQ17: ChatGPT-assisted evidence recharting, 2026-09-08 | AR17: RA | AS17: Not recorded; historical inclusion retained
A18: 14 | B18: Historical | C18: Functional neuroimaging of high-risk 6-month-old infants predicts a diagnosis of autism at 24 months of age | D18: 10.1126/scitranslmed.aag2882 | E18: 2017 | F18: Include | G18: =IF(F18="Include",1,0) -> 1 | H18: Prognosis | I18: Machine Learning | J18: Neuroimaging | K18: Not specified | L18: Multiple/not uniquely specified | M18: Research only | N18: Risk/trajectory estimation | O18: Not observed in assessed sources | P18: Not observed in assessed sources | Q18: Not reported in assessed sources | R18: Not reported in assessed sources | S18: Not reported in assessed sources | T18: Not reported in assessed sources | U18: Not reported in assessed sources | V18: Not reported in assessed sources | W18: Not reported in assessed sources | X18: Not reported in assessed sources | Y18: Reported | Z18: Not reported in assessed sources | AA18: Not recorded | AB18: 0 | AC18: 0 | AD18: =IF(AND(G18=1,AB18=0),1,0) -> 1 | AE18: =IF(AND(AD18=1,AC18=0),1,0) -> 1 | AF18: =IF(AND(G18=1,H18<>"Not specified"),1,0) -> 1 | AG18: =IF(AND(AE18=1,AF18=1),1,0) -> 1 | AH18: Supplied abstract/coding notes; no new full-text verification | AI18: https://doi.org/10.1126/scitranslmed.aag2882 | AJ18: EVIDENCIA; original abstract/coding notes and lot source trace; Historical signals: title/abstract/notes; full-text completion not independently established | AK18: Prospective infant fcMRI cohort predicts research diagnosis at 24 months using internal cross-validation. Prospective data collection is not prospective clinical use of model outputs. | AL18: Not applicable | AM18: Not separately specified | AO18: No additional status determination | AP18: Not documented for this recharting | AQ18: ChatGPT-assisted evidence recharting, 2026-09-08 | AR18: RA | AS18: Not recorded; historical inclusion retained
A19: 15 | B19: Historical | C19: Hybrid CNN and random forest model with late fusion for detection of autism spectrum disorder in Toddlers | D19: 10.1016/j.mex.2025.103278 | E19: 2025 | F19: Include | G19: =IF(F19="Include",1,0) -> 1 | H19: Screening | I19: Hybrid | J19: Multiple source categories | K19: VGG16 CNN + Random Forest (late fusion) | L19: Composite/ensemble pipeline | M19: Proposed only | N19: Triage/questionnaire assessment | O19: Pre-decision | P19: Not observed in assessed sources | Q19: Not reported in assessed sources | R19: Reported | S19: Not reported in assessed sources | T19: Not reported in assessed sources | U19: Not reported in assessed sources | V19: Not reported in assessed sources | W19: Reported | X19: Not reported in assessed sources | Y19: Not ascertainable | Z19: Not reported in assessed sources | AA19: Not recorded | AB19: 0 | AC19: 0 | AD19: =IF(AND(G19=1,AB19=0),1,0) -> 1 | AE19: =IF(AND(AD19=1,AC19=0),1,0) -> 1 | AF19: =IF(AND(G19=1,H19<>"Not specified"),1,0) -> 1 | AG19: =IF(AND(AE19=1,AF19=1),1,0) -> 1 | AH19: Supplied abstract/coding notes; no new full-text verification | AI19: https://doi.org/10.1016/j.mex.2025.103278 | AJ19: EVIDENCIA; original abstract/coding notes and lot source trace; Historical signals: title/abstract/notes; full-text completion not independently established | AK19: The source describes facial-image and questionnaire models with late fusion. Participant-level pairing and independence of the two datasets are not established by the abstract; no evaluated clinical workflow is claimed. | AL19: Not applicable | AM19: Not separately specified | AO19: No additional status determination | AP19: Not documented for this recharting | AQ19: ChatGPT-assisted evidence recharting, 2026-09-08 | AS19: Not recorded; historical inclusion retained
A20: 16 | B20: Historical | C20: Machine Learning Approaches for the Early Diagnosis of Autism Spectrum Disorder: A Systematic Framework | D20: 10.1007/978-3-031-81083-1_7 | E20: 2025 | F20: Include | G20: =IF(F20="Include",1,0) -> 1 | H20: Screening | I20: Machine Learning | J20: Structured clinical/questionnaire data | K20: Neural network (depth not specified) | L20: Multiple/not uniquely specified | M20: Proposed only | N20: Triage/questionnaire assessment | O20: Pre-decision | P20: Not observed in assessed sources | Q20: Not reported in assessed sources | R20: Not reported in assessed sources | S20: Not reported in assessed sources | T20: Not reported in assessed sources | U20: Not reported in assessed sources | V20: Not reported in assessed sources | W20: Not reported in assessed sources | X20: Not reported in assessed sources | Y20: Not ascertainable | Z20: Not reported in assessed sources | AA20: Not recorded | AB20: 0 | AC20: 0 | AD20: =IF(AND(G20=1,AB20=0),1,0) -> 1 | AE20: =IF(AND(AD20=1,AC20=0),1,0) -> 1 | AF20: =IF(AND(G20=1,H20<>"Not specified"),1,0) -> 1 | AG20: =IF(AND(AE20=1,AF20=1),1,0) -> 1 | AH20: Supplied abstract/coding notes; no new full-text verification | AI20: https://doi.org/10.1007/978-3-031-81083-1_7 | AJ20: EVIDENCIA; original abstract/coding notes and lot source trace; Historical signals: title/abstract/notes; full-text completion not independently established | AK20: The abstract describes screening-assessment datasets and neural-network training, with an intended early-screening system. Detailed architecture and deployment are not established. | AL20: Not applicable | AM20: Not separately specified | AO20: No additional status determination | AP20: Not documented for this recharting | AQ20: ChatGPT-assisted evidence recharting, 2026-09-08 | AS20: Not recorded; historical inclusion retained
A21: 17 | B21: Historical | C21: Machine learning classification of autism spectrum disorder based on reciprocity in naturalistic social interactions | D21: 10.1038/s41398-024-02802-5 | E21: 2024 | F21: Include | G21: =IF(F21="Include",1,0) -> 1 | H21: Diagnosis | I21: Machine Learning | J21: Behavioral images/video/gaze/movement | K21: SVM | L21: SVM | M21: Research only | N21: Automated measurement/classification | O21: Not observed in assessed sources | P21: Not observed in assessed sources | Q21: Not reported in assessed sources | R21: Not reported in assessed sources | S21: Not reported in assessed sources | T21: Not reported in assessed sources | U21: Not reported in assessed sources | V21: Not reported in assessed sources | W21: Not reported in assessed sources | X21: Not reported in assessed sources | Y21: Not ascertainable | Z21: Not reported in assessed sources | AA21: Not recorded | AB21: 0 | AC21: 0 | AD21: =IF(AND(G21=1,AB21=0),1,0) -> 1 | AE21: =IF(AND(AD21=1,AC21=0),1,0) -> 1 | AF21: =IF(AND(G21=1,H21<>"Not specified"),1,0) -> 1 | AG21: =IF(AND(AE21=1,AF21=1),1,0) -> 1 | AH21: Supplied abstract/coding notes; no new full-text verification | AI21: https://doi.org/10.1038/s41398-024-02802-5 | AJ21: EVIDENCIA; original abstract/coding notes and lot source trace; Historical signals: title/abstract/notes; full-text completion not independently established | AK21: Naturalistic interaction videos are computationally annotated and classified offline; the source explicitly places routine-care generalization in future work. | AL21: Not applicable | AM21: Not separately specified | AO21: No additional status determination | AP21: Not documented for this recharting | AQ21: ChatGPT-assisted evidence recharting, 2026-09-08 | AS21: Not recorded; historical inclusion retained
A22: 18 | B22: Historical | C22: Multiparametric MRI characterization and prediction in autism spectrum disorder using graph theory and machine learning | D22: 10.1371/journal.pone.0090405 | E22: 2014 | F22: Include | G22: =IF(F22="Include",1,0) -> 1 | H22: Diagnosis | I22: Machine Learning | J22: Neuroimaging | K22: Not specified | L22: Multiple/not uniquely specified | M22: Research only | N22: Automated measurement/classification | O22: Not observed in assessed sources | P22: Not observed in assessed sources | Q22: Not reported in assessed sources | R22: Reported | S22: Not reported in assessed sources | T22: Not reported in assessed sources | U22: Not reported in assessed sources | V22: Reported | W22: Reported | X22: Not reported in assessed sources | Y22: Not ascertainable | Z22: Not reported in assessed sources | AA22: Not recorded | AB22: 0 | AC22: 0 | AD22: =IF(AND(G22=1,AB22=0),1,0) -> 1 | AE22: =IF(AND(AD22=1,AC22=0),1,0) -> 1 | AF22: =IF(AND(G22=1,H22<>"Not specified"),1,0) -> 1 | AG22: =IF(AND(AE22=1,AF22=1),1,0) -> 1 | AH22: Supplied abstract/coding notes; no new full-text verification | AI22: https://doi.org/10.1371/journal.pone.0090405 | AJ22: EVIDENCIA; original abstract/coding notes and lot source trace; Historical signals: title/abstract/notes; full-text completion not independently established | AK22: Multiparametric MRI and graph-theoretic features are analyzed with machine learning, not necessarily a graph neural network. Multi-center data and multiple MRI-derived feature types are reported. | AL22: Not applicable | AM22: Not separately specified | AO22: No additional status determination | AP22: Not documented for this recharting | AQ22: ChatGPT-assisted evidence recharting, 2026-09-08 | AR22: RA | AS22: Not recorded; historical inclusion retained
A23: 19 | B23: Historical | C23: Multivariate Neural Connectivity Patterns in Early Infancy Predict Later Autism Symptoms | D23: 10.1016/j.bpsc.2020.06.003 | E23: 2021 | F23: Include | G23: =IF(F23="Include",1,0) -> 1 | H23: Prognosis | I23: Machine Learning | J23: Physiological signals | K23: Support vector regression | L23: SVM | M23: Research only | N23: Risk/trajectory estimation | O23: Not observed in assessed sources | P23: Not observed in assessed sources | Q23: Not reported in assessed sources | R23: Not reported in assessed sources | S23: Not reported in assessed sources | T23: Not reported in assessed sources | U23: Not reported in assessed sources | V23: Not reported in assessed sources | W23: Not reported in assessed sources | X23: Not reported in assessed sources | Y23: Reported | Z23: Not reported in assessed sources | AA23: Not recorded | AB23: 0 | AC23: 0 | AD23: =IF(AND(G23=1,AB23=0),1,0) -> 1 | AE23: =IF(AND(AD23=1,AC23=0),1,0) -> 1 | AF23: =IF(AND(G23=1,H23<>"Not specified"),1,0) -> 1 | AG23: =IF(AND(AE23=1,AF23=1),1,0) -> 1 | AH23: Supplied abstract/coding notes; no new full-text verification | AI23: https://doi.org/10.1016/j.bpsc.2020.06.003 | AJ23: EVIDENCIA; original abstract/coding notes and lot source trace; Historical signals: title/abstract/notes; full-text completion not independently established | AK23: Three-month EEG predicts ADOS scores at 18 months in a longitudinal research cohort. A future clinical endpoint distinguishes prognosis from cross-sectional diagnosis. | AL23: Not applicable | AM23: Not separately specified | AO23: No additional status determination | AP23: Not documented for this recharting | AQ23: ChatGPT-assisted evidence recharting, 2026-09-08 | AR23: RA | AS23: Not recorded; historical inclusion retained
A24: 20 | B24: Historical | C24: Testing the accuracy of an observation-based classifier for rapid detection of autism risk. | D24: 10.1038/tp.2014.65 | E24: 2014 | F24: Include | G24: =IF(F24="Include",1,0) -> 1 | H24: Screening | I24: Machine Learning | J24: Structured clinical/questionnaire data | K24: Alternating Decision Tree | L24: Decision tree/rules | M24: Proposed only | N24: Triage/questionnaire assessment | O24: Pre-decision | P24: Not observed in assessed sources | Q24: Reported | R24: Not reported in assessed sources | S24: Not reported in assessed sources | T24: Not reported in assessed sources | U24: Not reported in assessed sources | V24: Not reported in assessed sources | W24: Not reported in assessed sources | X24: Not reported in assessed sources | Y24: Not ascertainable | Z24: Not reported in assessed sources | AA24: Not recorded | AB24: 0 | AC24: 0 | AD24: =IF(AND(G24=1,AB24=0),1,0) -> 1 | AE24: =IF(AND(AD24=1,AC24=0),1,0) -> 1 | AF24: =IF(AND(G24=1,H24<>"Not specified"),1,0) -> 1 | AG24: =IF(AND(AE24=1,AF24=1),1,0) -> 1 | AH24: Supplied abstract/coding notes; no new full-text verification | AI24: https://doi.org/10.1038/tp.2014.65 | AJ24: EVIDENCIA; original abstract/coding notes and lot source trace; Historical signals: title/abstract/notes; full-text completion not independently established | AK24: A previously developed shortened ADOS classifier is tested on an independent 2616-child sample. This is external model evaluation but not an observed clinical triage deployment. | AL24: Not applicable | AM24: Not separately specified | AO24: No additional status determination | AP24: Not documented for this recharting | AQ24: ChatGPT-assisted evidence recharting, 2026-09-08 | AS24: Not recorded; historical inclusion retained
A25: 21 | B25: Historical | C25: Using deep learning to classify developmental differences in reaching and placing movements in children with and without autism spectrum disorder | D25: 10.1038/s41598-024-81652-z | E25: 2024 | F25: Include | G25: =IF(F25="Include",1,0) -> 1 | H25: Diagnosis | I25: Deep Learning | J25: Behavioral images/video/gaze/movement | K25: MLP | L25: MLP/ANN | M25: Research only | N25: Automated measurement/classification | O25: Not observed in assessed sources | P25: Not observed in assessed sources | Q25: Not reported in assessed sources | R25: Not reported in assessed sources | S25: Not reported in assessed sources | T25: Not reported in assessed sources | U25: Not reported in assessed sources | V25: Not reported in assessed sources | W25: Not reported in assessed sources | X25: Not reported in assessed sources | Y25: Not ascertainable | Z25: Not reported in assessed sources | AA25: Not recorded | AB25: 0 | AC25: 0 | AD25: =IF(AND(G25=1,AB25=0),1,0) -> 1 | AE25: =IF(AND(AD25=1,AC25=0),1,0) -> 1 | AF25: =IF(AND(G25=1,H25<>"Not specified"),1,0) -> 1 | AG25: =IF(AND(AE25=1,AF25=1),1,0) -> 1 | AH25: Supplied abstract/coding notes; no new full-text verification | AI25: https://doi.org/10.1038/s41598-024-81652-z | AJ25: EVIDENCIA; original abstract/coding notes and lot source trace; Historical signals: title/abstract/notes; full-text completion not independently established | AK25: Deep classification uses reaching/placing movement kinematics; age groups and diagnostic labels are not separate data modalities. Clinical deployment is not evaluated. | AL25: Not applicable | AM25: Not separately specified | AO25: No additional status determination | AP25: Not documented for this recharting | AQ25: ChatGPT-assisted evidence recharting, 2026-09-08 | AS25: Not recorded; historical inclusion retained
A26: 22 | B26: Historical | C26: A CNN deep local and global ASD classification approach with continuous wavelet transform using task-based FMRI | D26: 10.3390/s21175822 | E26: 2021 | F26: Include | G26: =IF(F26="Include",1,0) -> 1 | H26: Diagnosis | I26: Deep Learning | J26: Neuroimaging | K26: CNN | L26: CNN | M26: Proposed only | N26: Diagnostic decision support | O26: In-decision | P26: Not observed in assessed sources | Q26: Not reported in assessed sources | R26: Not reported in assessed sources | S26: Reported | T26: Not reported in assessed sources | U26: Not reported in assessed sources | V26: Not reported in assessed sources | W26: Not reported in assessed sources | X26: Not reported in assessed sources | Y26: Not ascertainable | Z26: Reported | AA26: Not recorded | AB26: 0 | AC26: 0 | AD26: =IF(AND(G26=1,AB26=0),1,0) -> 1 | AE26: =IF(AND(AD26=1,AC26=0),1,0) -> 1 | AF26: =IF(AND(G26=1,H26<>"Not specified"),1,0) -> 1 | AG26: =IF(AND(AE26=1,AF26=1),1,0) -> 1 | AH26: Supplied abstract/coding notes; no new full-text verification | AI26: https://doi.org/10.3390/s21175822 | AJ26: EVIDENCIA; original abstract/coding notes and lot source trace; Historical signals: title/abstract/notes; full-text completion not independently established | AK26: Task-fMRI CAD with local/global CNN classifiers and a proposed severity map. Speech is the eliciting stimulus, not the model's audio input. Clinical interpretation remains proposed. | AL26: Not applicable | AM26: Not separately specified | AO26: No additional status determination | AP26: Not documented for this recharting | AQ26: ChatGPT-assisted evidence recharting, 2026-09-08 | AS26: Not recorded; historical inclusion retained
A27: 23 | B27: Historical | C27: A new machine learning model based on induction of rules for autism detection | D27: 10.1177/1460458218824711 | E27: 2020 | F27: Include | G27: =IF(F27="Include",1,0) -> 1 | H27: Screening | I27: Machine Learning | J27: Structured clinical/questionnaire data | K27: Rule induction (Rules-Machine Learning) | L27: Decision tree/rules | M27: Proposed only | N27: Triage/questionnaire assessment | O27: Pre-decision | P27: Not observed in assessed sources | Q27: Not reported in assessed sources | R27: Not reported in assessed sources | S27: Reported | T27: Not reported in assessed sources | U27: Not reported in assessed sources | V27: Not reported in assessed sources | W27: Not reported in assessed sources | X27: Not reported in assessed sources | Y27: Not ascertainable | Z27: Reported | AA27: Not recorded | AB27: 0 | AC27: 0 | AD27: =IF(AND(G27=1,AB27=0),1,0) -> 1 | AE27: =IF(AND(AD27=1,AC27=0),1,0) -> 1 | AF27: =IF(AND(G27=1,H27<>"Not specified"),1,0) -> 1 | AG27: =IF(AND(AE27=1,AF27=1),1,0) -> 1 | AH27: Supplied abstract/coding notes; no new full-text verification | AI27: https://doi.org/10.1177/1460458218824711 | AJ27: EVIDENCIA; original abstract/coding notes and lot source trace; Historical signals: title/abstract/notes; full-text completion not independently established | AK27: Questionnaire-derived datasets support a rule-learning classifier whose rules are intended for domain-expert interpretation. Retain the specified rule family rather than forcing a decision-tree label. | AL27: Not applicable | AM27: Not separately specified | AO27: No additional status determination | AP27: Not documented for this recharting | AQ27: ChatGPT-assisted evidence recharting, 2026-09-08 | AR27: RA | AS27: Not recorded; historical inclusion retained
A28: 24 | B28: Historical | C28: A Novel Grading System for Autism Severity Level Using Task-Based Functional MRI: A Response to Speech Study | D28: 10.1109/access.2021.3097606 | E28: 2021 | F28: Include | G28: =IF(F28="Include",1,0) -> 1 | H28: Diagnosis | I28: Machine Learning | J28: Neuroimaging | K28: Multiple classifiers (primary not specified) | L28: Multiple/not uniquely specified | M28: Proposed only | N28: Diagnostic decision support | O28: In-decision | P28: Not observed in assessed sources | Q28: Not reported in assessed sources | R28: Not reported in assessed sources | S28: Not reported in assessed sources | T28: Not reported in assessed sources | U28: Not reported in assessed sources | V28: Not reported in assessed sources | W28: Not reported in assessed sources | X28: Not reported in assessed sources | Y28: Not ascertainable | Z28: Not reported in assessed sources | AA28: Not recorded | AB28: 0 | AC28: 0 | AD28: =IF(AND(G28=1,AB28=0),1,0) -> 1 | AE28: =IF(AND(AD28=1,AC28=0),1,0) -> 1 | AF28: =IF(AND(G28=1,H28<>"Not specified"),1,0) -> 1 | AG28: =IF(AND(AE28=1,AF28=1),1,0) -> 1 | AH28: Supplied abstract/coding notes; no new full-text verification | AI28: https://doi.org/10.1109/access.2021.3097606 | AJ28: EVIDENCIA; original abstract/coding notes and lot source trace; Historical signals: title/abstract/notes; full-text completion not independently established | AK28: A task-fMRI framework grades contemporaneous ASD severity. Speech stimulation is not voice-data modeling; oversampling and repeated random splits are internal validation only. | AL28: Not applicable | AM28: Not separately specified | AO28: No additional status determination | AP28: Not documented for this recharting | AQ28: ChatGPT-assisted evidence recharting, 2026-09-08 | AR28: RA | AS28: Not recorded; historical inclusion retained
A29: 26 | B29: Historical | C29: An Analysis of the Use of Machine Learning in the Diagnosis of Autism Spectrum Disorder | D29: 10.1007/978-3-031-23683-9_12 | E29: 2023 | F29: Exclude | G29: =IF(F29="Include",1,0) -> 0 | H29: Excluded | I29: Excluded | J29: Excluded | K29: Not specified | L29: Multiple/not uniquely specified | M29: Excluded | N29: Excluded | O29: Not applicable - excluded | P29: Not applicable - excluded | Q29: Not reported in assessed sources | R29: Not ascertainable | S29: Not reported in assessed sources | T29: Not reported in assessed sources | U29: Not reported in assessed sources | V29: Not reported in assessed sources | W29: Reported | X29: Not reported in assessed sources | Y29: Not ascertainable | Z29: Not reported in assessed sources | AA29: Not recorded | AB29: 0 | AC29: 0 | AD29: =IF(AND(G29=1,AB29=0),1,0) -> 0 | AE29: =IF(AND(AD29=1,AC29=0),1,0) -> 0 | AF29: =IF(AND(G29=1,H29<>"Not specified"),1,0) -> 0 | AG29: =IF(AND(AE29=1,AF29=1),1,0) -> 0 | AH29: Supplied abstract/coding notes; no new full-text verification | AI29: https://link.springer.com/chapter/10.1007/978-3-031-23683-9_12 | AJ29: EVIDENCIA; original abstract/coding notes and lot source trace; Historical signals: title/abstract/notes; full-text completion not independently established | AK29: The publication identifies itself as a survey of machine-learning techniques and prior reported performance rather than an original empirical ASD model evaluation. | AL29: EC1 - Secondary / non-empirical publication | AM29: Not separately specified | AO29: No additional status determination | AP29: Not documented for this recharting | AQ29: ChatGPT-assisted evidence recharting, 2026-09-08 | AS29: Not recorded; historical inclusion retained
A30: 27 | B30: Historical | C30: An analytics-driven model for identifying autism spectrum disorder using eye tracking | D30: 10.1016/j.health.2025.100409 | E30: 2025 | F30: Include | G30: =IF(F30="Include",1,0) -> 1 | H30: Screening | I30: Not specified | J30: Behavioral images/video/gaze/movement | K30: Multiple ML/DL models (primary not specified) | L30: Multiple/not uniquely specified | M30: Research only | N30: Triage/questionnaire assessment | O30: Not observed in assessed sources | P30: Not observed in assessed sources | Q30: Not reported in assessed sources | R30: Not reported in assessed sources | S30: Not reported in assessed sources | T30: Not reported in assessed sources | U30: Not reported in assessed sources | V30: Not reported in assessed sources | W30: Not reported in assessed sources | X30: Not reported in assessed sources | Y30: Not ascertainable | Z30: Not reported in assessed sources | AA30: Not recorded | AB30: 0 | AC30: 0 | AD30: =IF(AND(G30=1,AB30=0),1,0) -> 1 | AE30: =IF(AND(AD30=1,AC30=0),1,0) -> 1 | AF30: =IF(AND(G30=1,H30<>"Not specified"),1,0) -> 1 | AG30: =IF(AND(AE30=1,AF30=1),1,0) -> 1 | AH30: Supplied abstract/coding notes; no new full-text verification | AI30: https://doi.org/10.1016/j.health.2025.100409 | AJ30: EVIDENCIA; original abstract/coding notes and lot source trace; Historical signals: title/abstract/notes; full-text completion not independently established | AK30: Saliency4ASD eye-movement features are evaluated with several ML/DL models. The assessed material does not identify one primary model; comparison alone does not establish a hybrid architecture. | AL30: Not applicable | AM30: Not separately specified | AO30: No additional status determination | AP30: Not documented for this recharting | AQ30: ChatGPT-assisted evidence recharting, 2026-09-08 | AR30: RA | AS30: Not recorded; historical inclusion retained
A31: 28 | B31: Historical | C31: An evaluation of machine learning approaches for early diagnosis of autism spectrum disorder | D31: 10.1016/j.health.2023.100293 | E31: 2024 | F31: Include | G31: =IF(F31="Include",1,0) -> 1 | H31: Screening | I31: Machine Learning | J31: Structured clinical/questionnaire data | K31: Neural network (combined dataset); SVM/LR comparators | L31: SVM | M31: Research only | N31: Triage/questionnaire assessment | O31: Not observed in assessed sources | P31: Not observed in assessed sources | Q31: Not reported in assessed sources | R31: Not reported in assessed sources | S31: Not reported in assessed sources | T31: Not reported in assessed sources | U31: Not reported in assessed sources | V31: Not reported in assessed sources | W31: Not reported in assessed sources | X31: Not reported in assessed sources | Y31: Not ascertainable | Z31: Not reported in assessed sources | AA31: Not recorded | AB31: 0 | AC31: 0 | AD31: =IF(AND(G31=1,AB31=0),1,0) -> 1 | AE31: =IF(AND(AD31=1,AC31=0),1,0) -> 1 | AF31: =IF(AND(G31=1,H31<>"Not specified"),1,0) -> 1 | AG31: =IF(AND(AE31=1,AF31=1),1,0) -> 1 | AH31: Supplied abstract/coding notes; no new full-text verification | AI31: https://doi.org/10.1016/j.health.2023.100293 | AJ31: EVIDENCIA; original abstract/coding notes and lot source trace; Historical signals: title/abstract/notes; full-text completion not independently established | AK31: Public age-specific screening datasets are analyzed with classification and clustering. The proposed ANN is emphasized for the pooled dataset; no prospective diagnostic use is shown. | AL31: Not applicable | AM31: Not separately specified | AO31: No additional status determination | AP31: Not documented for this recharting | AQ31: ChatGPT-assisted evidence recharting, 2026-09-08 | AR31: RA | AS31: Not recorded; historical inclusion retained
A32: 29 | B32: Historical | C32: An intellectual autism spectrum disorder classification framework in healthcare industry using ViT-based adaptive deep learning model | D32: 10.1016/j.bspc.2025.107737 | E32: 2025 | F32: Include | G32: =IF(F32="Include",1,0) -> 1 | H32: Diagnosis | I32: Deep Learning | J32: Neuroimaging | K32: ViT-ARDNet-LSTM | L32: Composite/ensemble pipeline | M32: Proposed only | N32: Diagnostic decision support | O32: In-decision | P32: Not observed in assessed sources | Q32: Not reported in assessed sources | R32: Not reported in assessed sources | S32: Not reported in assessed sources | T32: Not reported in assessed sources | U32: Not reported in assessed sources | V32: Not reported in assessed sources | W32: Not reported in assessed sources | X32: Not reported in assessed sources | Y32: Not ascertainable | Z32: Not reported in assessed sources | AA32: Not recorded | AB32: 0 | AC32: 0 | AD32: =IF(AND(G32=1,AB32=0),1,0) -> 1 | AE32: =IF(AND(AD32=1,AC32=0),1,0) -> 1 | AF32: =IF(AND(G32=1,H32<>"Not specified"),1,0) -> 1 | AG32: =IF(AND(AE32=1,AF32=1),1,0) -> 1 | AH32: Supplied abstract/coding notes; no new full-text verification | AI32: https://doi.org/10.1016/j.bspc.2025.107737 | AJ32: EVIDENCIA; original abstract/coding notes and lot source trace; Historical signals: title/abstract/notes; full-text completion not independently established | AK32: MRI classification uses a vision transformer, residual DenseNet and LSTM in a deep-learning architecture. Combining deep components is not ML/DL hybrid integration. | AL32: Not applicable | AM32: Not separately specified | AO32: No additional status determination | AP32: Not documented for this recharting | AQ32: ChatGPT-assisted evidence recharting, 2026-09-08 | AS32: Not recorded; historical inclusion retained
A33: 30 | B33: Historical | C33: Analysis and Detection of Autism Spectrum Disorder Using Machine Learning Techniques | D33: 10.1016/j.procs.2020.03.399 | E33: 2020 | F33: Include | G33: =IF(F33="Include",1,0) -> 1 | H33: Screening | I33: Deep Learning | J33: Structured clinical/questionnaire data | K33: CNN | L33: CNN | M33: Research only | N33: Triage/questionnaire assessment | O33: Not observed in assessed sources | P33: Not observed in assessed sources | Q33: Not reported in assessed sources | R33: Not reported in assessed sources | S33: Not reported in assessed sources | T33: Not reported in assessed sources | U33: Not reported in assessed sources | V33: Not reported in assessed sources | W33: Not reported in assessed sources | X33: Not reported in assessed sources | Y33: Not ascertainable | Z33: Not reported in assessed sources | AA33: Not recorded | AB33: 0 | AC33: 0 | AD33: =IF(AND(G33=1,AB33=0),1,0) -> 1 | AE33: =IF(AND(AD33=1,AC33=0),1,0) -> 1 | AF33: =IF(AND(G33=1,H33<>"Not specified"),1,0) -> 1 | AG33: =IF(AND(AE33=1,AF33=1),1,0) -> 1 | AH33: Supplied abstract/coding notes; no new full-text verification | AI33: https://doi.org/10.1016/j.procs.2020.03.399 | AJ33: EVIDENCIA; original abstract/coding notes and lot source trace; Historical signals: title/abstract/notes; full-text completion not independently established | AK33: Three public tabular screening datasets are evaluated. CNN is the reported best-performing model; evaluating conventional ML baselines does not make this a hybrid model. | AL33: Not applicable | AM33: Not separately specified | AO33: No additional status determination | AP33: Not documented for this recharting | AQ33: ChatGPT-assisted evidence recharting, 2026-09-08 | AS33: Not recorded; historical inclusion retained
A34: 31 | B34: Historical | C34: ASD classification for children using deep neural network | D34: 10.1016/j.gltp.2021.08.042 | E34: 2021 | F34: Include | G34: =IF(F34="Include",1,0) -> 1 | H34: Screening | I34: Deep Learning | J34: Structured clinical/questionnaire data | K34: DNN with diffusion mapping | L34: Other specified method | M34: Research only | N34: Triage/questionnaire assessment | O34: Not observed in assessed sources | P34: Not observed in assessed sources | Q34: Not reported in assessed sources | R34: Not reported in assessed sources | S34: Not reported in assessed sources | T34: Not reported in assessed sources | U34: Not reported in assessed sources | V34: Not reported in assessed sources | W34: Not reported in assessed sources | X34: Not reported in assessed sources | Y34: Not ascertainable | Z34: Not reported in assessed sources | AA34: Not recorded | AB34: 0 | AC34: 0 | AD34: =IF(AND(G34=1,AB34=0),1,0) -> 1 | AE34: =IF(AND(AD34=1,AC34=0),1,0) -> 1 | AF34: =IF(AND(G34=1,H34<>"Not specified"),1,0) -> 1 | AG34: =IF(AND(AE34=1,AF34=1),1,0) -> 1 | AH34: Supplied abstract/coding notes; no new full-text verification | AI34: https://doi.org/10.1016/j.gltp.2021.08.042 | AJ34: EVIDENCIA; original abstract/coding notes and lot source trace; Historical signals: title/abstract/notes; full-text completion not independently established | AK34: A UCI child screening dataset is classified using a DNN. The word diagnosis does not demonstrate specialist diagnostic workflow use. | AL34: Not applicable | AM34: Not separately specified | AO34: No additional status determination | AP34: Not documented for this recharting | AQ34: ChatGPT-assisted evidence recharting, 2026-09-08 | AS34: Not recorded; historical inclusion retained
